Workbook

Sheet Schema!!!!!!
B1: ronde 1 | F1: ronde 2 | J1: ronde 3 | O1: T1
A2: Salty potato in the hole | B2: =O10 -> T10 | C2: =O21 -> T21 | D2: =O28 -> T28 | E2: =O35 -> T35 | F2: =B5 -> T16 | G2: =C3 -> T27 | H2: =D4 -> T20 | I2: =E4 -> T26 | J2: =F5 -> T14 | K2: =G3 -> T19 | L2: =H3 -> T38 | M2: =I4 -> T38 | O2: T2
A3: Pony Polo | B3: =O18 -> T18 | C3: =O27 -> T27 | D3: =O31 -> T31 | E3: =O38 -> T38 | F3: =B2 -> T10 | G3: =C4 -> T19 | H3: =D5 -> T38 | I3: =E5 -> T39 | J3: =F2 -> T16 | K3: =G4 -> T30 | L3: =H4 -> T28 | M3: =I5 -> T35 | O3: T3
A4: Straat van Hormuz | B4: =O14 -> T14 | C4: =O19 -> T19 | D4: =O20 -> T20 | E4: =O26 -> T26 | F4: =#REF! -> #REF! | G4: =C5 -> T30 | H4: =D2 -> T28 | I4: =E3 -> T38 | J4: =F3 -> T10 | K4: =G5 -> T21 | L4: =H5 -> T31 | M4: =I3 -> T39 | O4: T4
A5: Red Claes Compaen | B5: =O16 -> T16 | C5: =O30 -> T30 | D5: =O38 -> T38 | E5: =O39 -> T39 | F5: =B4 -> T14 | G5: =C2 -> T21 | H5: =D3 -> T31 | I5: =E2 -> T35 | J5: =F4 -> #REF! | K5: =G2 -> T27 | L5: =H2 -> T20 | M5: =I2 -> T26 | O5: T5
A6: Nick’s Weekendspecial | B6: =O2 -> T2 | C6: =O8 -> T8 | D6: =O11 -> T11 | E6: =O23 -> T23 | F6: =B10 -> T1 | G6: =C8 -> T32 | H6: =D9 -> T24 | I6: =E7 -> T34 | J6: =F10 -> T3 | K6: =G7 -> T15 | L6: =H9 -> T31 | M6: =I7 -> T40 | O6: T6
A7: Danoontje Powerrrrrr | B7: =O7 -> T7 | C7: =O9 -> T9 | D7: =O31 -> T31 | E7: =O34 -> T34 | F7: =B6 -> T2 | G7: =C9 -> T15 | H7: =D10 -> T5 | I7: =E8 -> T40 | J7: =F6 -> T1 | K7: =G8 -> T4 | L7: =H10 -> T37 | M7: =I8 -> T25 | O7: T7
A8: Kamelenrace | B8: =O12 -> T12 | C8: =O32 -> T32 | D8: =O37 -> T37 | E8: =O40 -> T40 | F8: =B7 -> T7 | G8: =C10 -> T4 | H8: =D6 -> T11 | I8: =E9 -> T25 | J8: =F7 -> T2 | K8: =G9 -> T8 | L8: =H6 -> T24 | M8: =I9 -> T6 | O8: T8
A9: Memory Romy | B9: =O3 -> T3 | C9: =O15 -> T15 | D9: =O24 -> T24 | E9: =O25 -> T25 | F9: =B8 -> T12 | G9: =C6 -> T8 | H9: =D7 -> T31 | I9: =E10 -> T6 | J9: =F8 -> T7 | K9: =G10 -> T9 | L9: =H7 -> T5 | M9: =I10 -> T23 | O9: T9
A10: PAUZE RONDE | B10: =O1 -> T1 | C10: =O4 -> T4 | D10: =O5 -> T5 | E10: =O6 -> T6 | F10: =B9 -> T3 | G10: =C7 -> T9 | H10: =D8 -> T37 | I10: =E6 -> T23 | J10: =F9 -> T12 | K10: =G6 -> T32 | L10: =H8 -> T11 | M10: =I6 -> T34 | O10: T10
B11: =O13 -> T13 | C11: =O17 -> T17 | D11: =O22 -> T22 | E11: =O29 -> T29 | O11: T11
B12: ronde 4 | F12: ronde 5 | O12: T12
A13: =A2 -> Salty potato in the hole | B13: =#REF! -> #REF! | C13: =C5 -> T30 | D13: =L4 -> T31 | E13: =E5 -> T39 | F13: ← (PAUZE) voor de teams hiernaast | O13: T13
A14: =A3 -> Pony Polo | B14: =B4 -> T14 | C14: =C2 -> T21 | D14: =L5 -> T20 | E14: =E4 -> T26 | O14: T14
A15: =A4 -> Straat van Hormuz | B15: =B5 -> T16 | C15: =C3 -> T27 | D15: =L2 -> T38 | E15: =E2 -> T35 | O15: T15
A16: =A5 -> Red Claes Compaen | B16: =B2 -> T10 | C16: =C4 -> T19 | D16: =D2 -> T28 | E16: =E3 -> T38 | O16: T16
A17: =A6 -> Nick’s Weekendspecial | B17: =B8 -> T12 | C17: =C10 -> T4 | D17: =D10 -> T5 | E17: =E9 -> T25 | F17: =B21 -> T7 | G17: =C19 -> T9 | H17: =D20 -> T37 | I17: =I9 -> T6 | O17: T17
A18: =A7 -> Danoontje Powerrrrrr | B18: =B9 -> T3 | C18: =C6 -> T8 | D18: =D6 -> T11 | E18: =E10 -> T6 | F18: =B17 -> T12 | G18: =C20 -> T32 | H18: =D21 -> T24 | I18: =E19 -> T23 | O18: T18
A19: =A8 -> Kamelenrace | B19: =B10 -> T1 | C19: =C7 -> T9 | D19: =D7 -> T31 | E19: =E6 -> T23 | F19: =B18 -> T3 | G19: =C21 -> T15 | H19: =H7 -> T5 | I19: =I6 -> T34 | O19: T19
A20: =A9 -> Memory Romy | B20: =B6 -> T2 | C20: =C8 -> T32 | D20: =D8 -> T37 | E20: =E7 -> T34 | F20: =B19 -> T1 | G20: =C17 -> T4 | H20: =D18 -> T11 | I20: =I7 -> T40 | O20: T20
A21: PAUZE RONDE | B21: =B7 -> T7 | C21: =C9 -> T15 | D21: =D9 -> T24 | E21: =E8 -> T40 | F21: =B20 -> T2 | G21: =C18 -> T8 | H21: =D19 -> T31 | I21: =E17 -> T25 | O21: T21
O22: T22
B23: ronde 6 | F23: ronde 7 | J23: ronde 8 | O23: T23
A24: =A2 -> Salty potato in the hole | B24: =B20 -> T2 | C24: =B21 -> T7 | D24: =B17 -> T12 | E24: =B18 -> T3 | F24: =B28 -> T34 | G24: =C26 -> T4 | H24: =D27 -> T5 | I24: =E25 -> T32 | J24: =F28 -> T37 | K24: =G25 -> T24 | L24: =H27 -> T9 | M24: =I25 -> T31 | O24: T24
A25: =A14 -> Pony Polo | B25: =B19 -> T1 | C25: =C18 -> T8 | D25: =C19 -> T9 | E25: =C20 -> T32 | F25: =B24 -> T2 | G25: =C27 -> T24 | H25: =D28 -> T25 | I25: =E26 -> T31 | J25: =F24 -> T34 | K25: =G26 -> T40 | L25: =H28 -> T11 | M25: =I26 -> T23 | O25: T25
A26: =A15 -> Straat van Hormuz | B26: =C21 -> T15 | C26: =C17 -> T4 | D26: =D18 -> T11 | E26: =D19 -> T31 | F26: =B25 -> T1 | G26: =C28 -> T40 | H26: =D24 -> T12 | I26: =E27 -> T23 | J26: =F25 -> T2 | K26: =G27 -> T7 | L26: =H24 -> T5 | M26: =I27 -> T6 | O26: T26
A27: =A16 -> Red Claes Compaen | B27: =D20 -> T37 | C27: =D21 -> T24 | D27: =D17 -> T5 | E27: =E19 -> T23 | F27: =B26 -> T15 | G27: =C24 -> T7 | H27: =D25 -> T9 | I27: =E28 -> T6 | J27: =F26 -> T1 | K27: =G28 -> T8 | L27: =H25 -> T25 | M27: =I28 -> T3 | O27: T27
A28: PAUZE RONDE | B28: =E20 -> T34 | C28: =E21 -> T40 | D28: =E17 -> T25 | E28: =E18 -> T6 | F28: =B27 -> T37 | G28: =C25 -> T8 | H28: =D26 -> T11 | I28: =E24 -> T3 | J28: =F27 -> T15 | K28: =G24 -> T4 | L28: =H26 -> T12 | M28: =I24 -> T32 | O28: T28
A29: =A17 -> Nick’s Weekendspecial | B29: =B16 -> T10 | C29: =C15 -> T27 | D29: =D14 -> T20 | E29: =E16 -> T38 | F29: =B32 -> T14 | G29: =C30 -> T19 | H29: =D32 -> T31 | I29: =E31 -> T26 | J29: =F32 -> #REF! | K29: =G30 -> T21 | L29: =H32 -> T38 | M29: =I31 -> T39 | O29: T29
A30: =A18 -> Danoontje Powerrrrrr | B30: =B15 -> T16 | C30: =C16 -> T19 | D30: =D15 -> T38 | E30: =E13 -> T39 | F30: =B29 -> T10 | G30: =C31 -> T21 | H30: =D31 -> T28 | I30: =E32 -> T35 | J30: =F29 -> T14 | K30: =G31 -> T30 | L30: =H31 -> T20 | M30: =I32 -> T38 | O30: T30
A31: =A19 -> Kamelenrace | B31: =B13 -> #REF! | C31: =C14 -> T21 | D31: =D16 -> T28 | E31: =E14 -> T26 | F31: =B30 -> T16 | G31: =C32 -> T30 | H31: =D29 -> T20 | I31: =E30 -> T39 | J31: =F30 -> T10 | K31: =G32 -> T27 | L31: =H29 -> T31 | M31: =I30 -> T35 | O31: T31
A32: =A20 -> Memory Romy | B32: =B14 -> T14 | C32: =C13 -> T30 | D32: =D13 -> T31 | E32: =E15 -> T35 | F32: =B31 -> #REF! | G32: =C29 -> T27 | H32: =D30 -> T38 | I32: =E29 -> T38 | J32: =F31 -> T16 | K32: =G29 -> T19 | L32: =H30 -> T28 | M32: =I29 -> T26 | O32: T32
O33: T33
B34: ronde 9 | F34: ronde 10 | O34: T34
A35: =A24 -> Salty potato in the hole | B35: =B26 -> T15 | C35: =C28 -> T40 | D35: =D28 -> T25 | E35: =E27 -> T23 | F35: =B39 -> T1 | G35: =C37 -> T8 | H35: =D38 -> T11 | I35: =E36 -> T6 | O35: T35
A36: =A25 -> Pony Polo | B36: =B27 -> T37 | C36: =C24 -> T7 | D36: =D24 -> T12 | E36: =E28 -> T6 | F36: =B35 -> T15 | G36: =C38 -> T4 | H36: =D39 -> T5 | I36: =E37 -> T3 | O36: T36
A37: =A26 -> Straat van Hormuz | B37: =B28 -> T34 | C37: =C25 -> T8 | D37: =D25 -> T9 | E37: =E24 -> T3 | F37: =B36 -> T37 | G37: =C39 -> T24 | H37: =D35 -> T25 | I37: =E38 -> T32 | O37: T37
A38: =A27 -> Red Claes Compaen | B38: =B24 -> T2 | C38: =C26 -> T4 | D38: =D26 -> T11 | E38: =E25 -> T32 | F38: =B37 -> T34 | G38: =C36 -> T7 | H38: =D36 -> T12 | I38: =E39 -> T31 | O38: T38
A39: PAUZE RONDE | B39: =B25 -> T1 | C39: =C27 -> T24 | D39: =D27 -> T5 | E39: =E26 -> T31 | F39: =B38 -> T2 | G39: =C35 -> T40 | H39: =D37 -> T9 | I39: =E35 -> T23 | O39: T39
A40: =A29 -> Nick’s Weekendspecial | B40: =B30 -> T16 | C40: =C32 -> T30 | D40: =D31 -> T28 | E40: =E32 -> T35 | F40: =F13 -> ← (PAUZE) voor de teams hiernaast | O40: T40
...

Sheet Salty potato
B1: ='Schema!!!!!!'!B1 -> ronde 1 | K1: ='Schema!!!!!!'!B12 -> ronde 4 | T1: ='Schema!!!!!!'!F23 -> ronde 7 | AC1: ='Schema!!!!!!'!F34 -> ronde 10
B2: ='Schema!!!!!!'!A13 -> Salty potato in the hole | K2: =B2 -> Salty potato in the hole | T2: =K2 -> Salty potato in the hole | AC2: =T2 -> Salty potato in the hole
B3: ='Schema!!!!!!'!B2 -> T10 | C3: ='Schema!!!!!!'!C2 -> T21 | D3: ='Schema!!!!!!'!D2 -> T28 | E3: ='Schema!!!!!!'!E2 -> T35 | K3: ='Schema!!!!!!'!B13 -> #REF! | L3: ='Schema!!!!!!'!C13 -> T30 | M3: ='Schema!!!!!!'!D13 -> T31 | N3: ='Schema!!!!!!'!E13 -> T39 | T3: ='Schema!!!!!!'!F24 -> T34 | U3: ='Schema!!!!!!'!G24 -> T4 | V3: ='Schema!!!!!!'!H24 -> T5 | W3: ='Schema!!!!!!'!I24 -> T32 | AC3: ='Schema!!!!!!'!F35 -> T1 | AD3: ='Schema!!!!!!'!G35 -> T8 | AE3: ='Schema!!!!!!'!H35 -> T11 | AF3: ='Schema!!!!!!'!I35 -> T6
B5: =B3 -> T10 | E5: =C3 -> T21 | K5: =K3 -> #REF! | N5: =L3 -> T30 | T5: =T3 -> T34 | W5: =U3 -> T4 | AC5: =AC3 -> T1 | AF5: =AD3 -> T8
B8: =D3 -> T28 | E8: =E3 -> T35 | K8: =M3 -> T31 | N8: =N3 -> T39 | T8: =V3 -> T5 | W8: =W3 -> T32 | AC8: =AE3 -> T11 | AF8: =AF3 -> T6
B12: ='Schema!!!!!!'!F1 -> ronde 2 | K12: ='Schema!!!!!!'!F12 -> ronde 5 | T12: ='Schema!!!!!!'!J23 -> ronde 8
B13: =B2 -> Salty potato in the hole | K13: =K2 -> Salty potato in the hole | T13: =T2 -> Salty potato in the hole
B14: ='Schema!!!!!!'!F2 -> T16 | C14: ='Schema!!!!!!'!G2 -> T27 | D14: ='Schema!!!!!!'!H2 -> T20 | E14: ='Schema!!!!!!'!I2 -> T26 | K14: ='Schema!!!!!!'!F13 -> ← (PAUZE) voor de teams hiernaast | T14: ='Schema!!!!!!'!J24 -> T37 | U14: ='Schema!!!!!!'!K24 -> T24 | V14: ='Schema!!!!!!'!L24 -> T9 | W14: ='Schema!!!!!!'!M24 -> T31
B16: =B14 -> T16 | E16: =C14 -> T27 | T16: =T14 -> T37 | W16: =U14 -> T24
B19: =D14 -> T20 | E19: =E14 -> T26 | T19: =V14 -> T9 | W19: =W14 -> T31
B26: ='Schema!!!!!!'!J1 -> ronde 3 | K26: ='Schema!!!!!!'!B23 -> ronde 6 | T26: ='Schema!!!!!!'!B34 -> ronde 9
B27: =B2 -> Salty potato in the hole | K27: =K2 -> Salty potato in the hole | T27: =T13 -> Salty potato in the hole
B28: ='Schema!!!!!!'!J2 -> T14 | C28: ='Schema!!!!!!'!K2 -> T19 | D28: ='Schema!!!!!!'!L2 -> T38 | E28: ='Schema!!!!!!'!M2 -> T38 | K28: ='Schema!!!!!!'!B24 -> T2 | L28: ='Schema!!!!!!'!C24 -> T7 | M28: ='Schema!!!!!!'!D24 -> T12 | N28: ='Schema!!!!!!'!E24 -> T3 | T28: ='Schema!!!!!!'!B35 -> T15 | U28: ='Schema!!!!!!'!C35 -> T40 | V28: ='Schema!!!!!!'!D35 -> T25 | W28: ='Schema!!!!!!'!E35 -> T23
B30: =B28 -> T14 | E30: =C28 -> T19 | K30: =K28 -> T2 | N30: =L28 -> T7 | T30: =T28 -> T15 | W30: =U28 -> T40
B33: =D28 -> T38 | E33: =E28 -> T38 | K33: =M28 -> T12 | N33: =N28 -> T3 | T33: =V28 -> T25 | W33: =W28 -> T23

Sheet Pony polo
B2: ='Schema!!!!!!'!B1 -> ronde 1 | K2: ='Schema!!!!!!'!B12 -> ronde 4 | T2: ='Schema!!!!!!'!F23 -> ronde 7 | AC2: ='Schema!!!!!!'!F34 -> ronde 10
B3: ='Schema!!!!!!'!A14 -> Pony Polo | K3: =B3 -> Pony Polo | T3: =K3 -> Pony Polo | AC3: =T3 -> Pony Polo
B4: ='Schema!!!!!!'!#REF! -> #REF! | C4: ='Schema!!!!!!'!C3 -> T27 | D4: ='Schema!!!!!!'!D3 -> T31 | E4: ='Schema!!!!!!'!E3 -> T38 | K4: ='Schema!!!!!!'!B14 -> T14 | L4: ='Schema!!!!!!'!C14 -> T21 | M4: ='Schema!!!!!!'!D14 -> T20 | N4: ='Schema!!!!!!'!E14 -> T26 | T4: ='Schema!!!!!!'!F25 -> T2 | U4: ='Schema!!!!!!'!G25 -> T24 | V4: ='Schema!!!!!!'!H25 -> T25 | W4: ='Schema!!!!!!'!I25 -> T31 | AC4: ='Schema!!!!!!'!F36 -> T15 | AD4: ='Schema!!!!!!'!G36 -> T4 | AE4: ='Schema!!!!!!'!H36 -> T5 | AF4: ='Schema!!!!!!'!I36 -> T3
B6: =B4 -> #REF! | E6: =C4 -> T27 | K6: =K4 -> T14 | N6: =L4 -> T21 | T6: =T4 -> T2 | W6: =U4 -> T24 | AC6: =AC4 -> T15 | AF6: =AD4 -> T4
B9: =D4 -> T31 | E9: =E4 -> T38 | K9: =M4 -> T20 | N9: =N4 -> T26 | T9: =V4 -> T25 | W9: =W4 -> T31 | AC9: =AE4 -> T5 | AF9: =AF4 -> T3
B12: =B4 -> #REF! | E12: =D4 -> T31 | K12: =K4 -> T14 | N12: =M4 -> T20 | T12: =T4 -> T2 | W12: =V4 -> T25 | AC12: =AC4 -> T15 | AF12: =AE4 -> T5
B15: =C4 -> T27 | E15: =E4 -> T38 | K15: =L4 -> T21 | N15: =N4 -> T26 | T15: =U4 -> T24 | W15: =W4 -> T31 | AC15: =AD4 -> T4 | AF15: =AF4 -> T3
B18: ='Schema!!!!!!'!F1 -> ronde 2 | K18: ='Schema!!!!!!'!F12 -> ronde 5 | T18: ='Schema!!!!!!'!J23 -> ronde 8
B19: =B3 -> Pony Polo | K19: =K3 -> Pony Polo | T19: =T3 -> Pony Polo
B20: ='Schema!!!!!!'!F3 -> T10 | C20: ='Schema!!!!!!'!G3 -> T19 | D20: ='Schema!!!!!!'!H3 -> T38 | E20: ='Schema!!!!!!'!I3 -> T39 | K20: ='Schema!!!!!!'!F13 -> ← (PAUZE) voor de teams hiernaast | T20: ='Schema!!!!!!'!J25 -> T34 | U20: ='Schema!!!!!!'!K25 -> T40 | V20: ='Schema!!!!!!'!L25 -> T11 | W20: ='Schema!!!!!!'!M25 -> T23
B22: =B20 -> T10 | E22: =C20 -> T19 | T22: =T20 -> T34 | W22: =U20 -> T40
B25: =D20 -> T38 | E25: =E20 -> T39 | T25: =V20 -> T11 | W25: =W20 -> T23
B28: =B20 -> T10 | E28: =D20 -> T38 | T28: =T20 -> T34 | W28: =V20 -> T11
B31: =C20 -> T19 | E31: =E20 -> T39 | T31: =U20 -> T40 | W31: =W20 -> T23
B35: ='Schema!!!!!!'!J1 -> ronde 3 | K35: ='Schema!!!!!!'!B23 -> ronde 6 | T35: ='Schema!!!!!!'!B34 -> ronde 9
B36: =B3 -> Pony Polo | K36: =K3 -> Pony Polo | T36: =T19 -> Pony Polo
B37: ='Schema!!!!!!'!J3 -> T16 | C37: ='Schema!!!!!!'!K3 -> T30 | D37: ='Schema!!!!!!'!L3 -> T28 | E37: ='Schema!!!!!!'!M3 -> T35 | K37: ='Schema!!!!!!'!B25 -> T1 | L37: ='Schema!!!!!!'!C25 -> T8 | M37: ='Schema!!!!!!'!D25 -> T9 | N37: ='Schema!!!!!!'!E25 -> T32 | T37: ='Schema!!!!!!'!B36 -> T37 | U37: ='Schema!!!!!!'!C36 -> T7 | V37: ='Schema!!!!!!'!D36 -> T12 | W37: ='Schema!!!!!!'!E36 -> T6
B39: =B37 -> T16 | E39: =C37 -> T30 | K39: =K37 -> T1 | N39: =L37 -> T8 | T39: =T37 -> T37 | W39: =U37 -> T7
B42: =D37 -> T28 | E42: =E37 -> T35 | K42: =M37 -> T9 | N42: =N37 -> T32 | T42: =V37 -> T12 | W42: =W37 -> T6
B45: =B37 -> T16 | E45: =D37 -> T28 | K45: =K37 -> T1 | N45: =M37 -> T9 | T45: =T37 -> T37 | W45: =V37 -> T12
B48: =C37 -> T30 | E48: =E37 -> T35 | K48: =L37 -> T8 | N48: =N37 -> T32 | T48: =U37 -> T7 | W48: =W37 -> T6

Sheet Straat van Hormuz
B3: ='Schema!!!!!!'!B1 -> ronde 1 | K3: ='Schema!!!!!!'!B12 -> ronde 4 | T3: ='Schema!!!!!!'!F23 -> ronde 7 | AC3: ='Schema!!!!!!'!F34 -> ronde 10
B4: ='Schema!!!!!!'!A15 -> Straat van Hormuz | K4: =B4 -> Straat van Hormuz | T4: =K4 -> Straat van Hormuz | AC4: =T4 -> Straat van Hormuz
B5: ='Schema!!!!!!'!B4 -> T14 | C5: ='Schema!!!!!!'!C4 -> T19 | D5: ='Schema!!!!!!'!D4 -> T20 | E5: ='Schema!!!!!!'!E4 -> T26 | K5: ='Schema!!!!!!'!B15 -> T16 | L5: ='Schema!!!!!!'!C15 -> T27 | M5: ='Schema!!!!!!'!D15 -> T38 | N5: ='Schema!!!!!!'!E15 -> T35 | T5: ='Schema!!!!!!'!F26 -> T1 | U5: ='Schema!!!!!!'!G26 -> T40 | V5: ='Schema!!!!!!'!H26 -> T12 | W5: ='Schema!!!!!!'!I26 -> T23 | AC5: ='Schema!!!!!!'!F37 -> T37 | AD5: ='Schema!!!!!!'!G37 -> T24 | AE5: ='Schema!!!!!!'!H37 -> T25 | AF5: ='Schema!!!!!!'!I37 -> T32
B7: =B5 -> T14 | E7: =C5 -> T19 | K7: =K5 -> T16 | N7: =L5 -> T27 | T7: =T5 -> T1 | W7: =U5 -> T40 | AC7: =AC5 -> T37 | AF7: =AD5 -> T24
B10: =D5 -> T20 | E10: =E5 -> T26 | K10: =M5 -> T38 | N10: =N5 -> T35 | T10: =V5 -> T12 | W10: =W5 -> T23 | AC10: =AE5 -> T25 | AF10: =AF5 -> T32
B14: ='Schema!!!!!!'!F1 -> ronde 2 | K14: ='Schema!!!!!!'!F12 -> ronde 5 | T14: ='Schema!!!!!!'!J23 -> ronde 8
B15: =B4 -> Straat van Hormuz | K15: =K4 -> Straat van Hormuz | T15: =T4 -> Straat van Hormuz
B16: ='Schema!!!!!!'!F4 -> #REF! | C16: ='Schema!!!!!!'!G4 -> T30 | D16: ='Schema!!!!!!'!H4 -> T28 | E16: ='Schema!!!!!!'!I4 -> T38 | K16: ='Schema!!!!!!'!F13 -> ← (PAUZE) voor de teams hiernaast | T16: ='Schema!!!!!!'!J26 -> T2 | U16: ='Schema!!!!!!'!K26 -> T7 | V16: ='Schema!!!!!!'!L26 -> T5 | W16: ='Schema!!!!!!'!M26 -> T6
B18: =B16 -> #REF! | E18: =C16 -> T30 | T18: =T16 -> T2 | W18: =U16 -> T7
B21: =D16 -> T28 | E21: =E16 -> T38 | T21: =V16 -> T5 | W21: =W16 -> T6
B28: ='Schema!!!!!!'!J1 -> ronde 3 | K28: ='Schema!!!!!!'!B23 -> ronde 6 | T28: ='Schema!!!!!!'!B34 -> ronde 9
B29: =B4 -> Straat van Hormuz | K29: =K4 -> Straat van Hormuz | T29: =T15 -> Straat van Hormuz
B30: ='Schema!!!!!!'!J4 -> T10 | C30: ='Schema!!!!!!'!K4 -> T21 | D30: ='Schema!!!!!!'!L4 -> T31 | E30: ='Schema!!!!!!'!M4 -> T39 | K30: ='Schema!!!!!!'!B26 -> T15 | L30: ='Schema!!!!!!'!C26 -> T4 | M30: ='Schema!!!!!!'!D26 -> T11 | N30: ='Schema!!!!!!'!E26 -> T31 | T30: ='Schema!!!!!!'!B37 -> T34 | U30: ='Schema!!!!!!'!C37 -> T8 | V30: ='Schema!!!!!!'!D37 -> T9 | W30: ='Schema!!!!!!'!E37 -> T3
B32: =B30 -> T10 | E32: =C30 -> T21 | K32: =K30 -> T15 | N32: =L30 -> T4 | T32: =T30 -> T34 | W32: =U30 -> T8
B35: =D30 -> T31 | E35: =E30 -> T39 | K35: =M30 -> T11 | N35: =N30 -> T31 | T35: =V30 -> T9 | W35: =W30 -> T3

Sheet Red Claes Compaen
B4: ='Schema!!!!!!'!B1 -> ronde 1 | K4: ='Schema!!!!!!'!B12 -> ronde 4 | T4: ='Schema!!!!!!'!F23 -> ronde 7 | AC4: ='Schema!!!!!!'!F34 -> ronde 10
B5: ='Schema!!!!!!'!A16 -> Red Claes Compaen | K5: =B5 -> Red Claes Compaen | T5: =K5 -> Red Claes Compaen | AC5: =T5 -> Red Claes Compaen
B6: ='Schema!!!!!!'!B5 -> T16 | C6: ='Schema!!!!!!'!C5 -> T30 | D6: ='Schema!!!!!!'!D5 -> T38 | E6: ='Schema!!!!!!'!E5 -> T39 | K6: ='Schema!!!!!!'!B16 -> T10 | L6: ='Schema!!!!!!'!C16 -> T19 | M6: ='Schema!!!!!!'!D16 -> T28 | N6: ='Schema!!!!!!'!E16 -> T38 | T6: ='Schema!!!!!!'!F27 -> T15 | U6: ='Schema!!!!!!'!G27 -> T7 | V6: ='Schema!!!!!!'!H27 -> T9 | W6: ='Schema!!!!!!'!I27 -> T6 | AC6: ='Schema!!!!!!'!F38 -> T34 | AD6: ='Schema!!!!!!'!G38 -> T7 | AE6: ='Schema!!!!!!'!H38 -> T12 | AF6: ='Schema!!!!!!'!I38 -> T31
B8: =B6 -> T16 | E8: =C6 -> T30 | K8: =K6 -> T10 | N8: =L6 -> T19 | T8: =T6 -> T15 | W8: =U6 -> T7 | AC8: =AC6 -> T34 | AF8: =AD6 -> T7
B11: =D6 -> T38 | E11: =E6 -> T39 | K11: =M6 -> T28 | N11: =N6 -> T38 | T11: =V6 -> T9 | W11: =W6 -> T6 | AC11: =AE6 -> T12 | AF11: =AF6 -> T31
B15: ='Schema!!!!!!'!F1 -> ronde 2 | K15: ='Schema!!!!!!'!F12 -> ronde 5 | T15: ='Schema!!!!!!'!J23 -> ronde 8
B16: =B5 -> Red Claes Compaen | K16: =K5 -> Red Claes Compaen | T16: =T5 -> Red Claes Compaen
B17: ='Schema!!!!!!'!F5 -> T14 | C17: ='Schema!!!!!!'!G5 -> T21 | D17: ='Schema!!!!!!'!H5 -> T31 | E17: ='Schema!!!!!!'!I5 -> T35 | K17: ='Schema!!!!!!'!F13 -> ← (PAUZE) voor de teams hiernaast | T17: ='Schema!!!!!!'!J27 -> T1 | U17: ='Schema!!!!!!'!K27 -> T8 | V17: ='Schema!!!!!!'!L27 -> T25 | W17: ='Schema!!!!!!'!M27 -> T3
B19: =B17 -> T14 | E19: =C17 -> T21 | T19: =T17 -> T1 | W19: =U17 -> T8
B22: =D17 -> T31 | E22: =E17 -> T35 | T22: =V17 -> T25 | W22: =W17 -> T3
B29: ='Schema!!!!!!'!J1 -> ronde 3 | K29: ='Schema!!!!!!'!B23 -> ronde 6 | T29: ='Schema!!!!!!'!B34 -> ronde 9
B30: =B5 -> Red Claes Compaen | K30: =K5 -> Red Claes Compaen | T30: =T16 -> Red Claes Compaen
B31: ='Schema!!!!!!'!J5 -> #REF! | C31: ='Schema!!!!!!'!K5 -> T27 | D31: ='Schema!!!!!!'!L5 -> T20 | E31: ='Schema!!!!!!'!M5 -> T26 | K31: ='Schema!!!!!!'!B27 -> T37 | L31: ='Schema!!!!!!'!C27 -> T24 | M31: ='Schema!!!!!!'!D27 -> T5 | N31: ='Schema!!!!!!'!E27 -> T23 | T31: ='Schema!!!!!!'!B38 -> T2 | U31: ='Schema!!!!!!'!C38 -> T4 | V31: ='Schema!!!!!!'!D38 -> T11 | W31: ='Schema!!!!!!'!E38 -> T32
B33: =B31 -> #REF! | E33: =C31 -> T27 | K33: =K31 -> T37 | N33: =L31 -> T24 | T33: =T31 -> T2 | W33: =U31 -> T4
B36: =D31 -> T20 | E36: =E31 -> T26 | K36: =M31 -> T5 | N36: =N31 -> T23 | T36: =V31 -> T11 | W36: =W31 -> T32

Sheet Nick eten
B1: ='Schema!!!!!!'!B1 -> ronde 1 | K1: ='Schema!!!!!!'!B12 -> ronde 4 | T1: ='Schema!!!!!!'!F23 -> ronde 7 | AC1: ='Schema!!!!!!'!F34 -> ronde 10
B2: ='Schema!!!!!!'!A6 -> Nick’s Weekendspecial | K2: =B2 -> Nick’s Weekendspecial | T2: =K2 -> Nick’s Weekendspecial | AC2: =T2 -> Nick’s Weekendspecial
B3: ='Schema!!!!!!'!B6 -> T2 | C3: ='Schema!!!!!!'!C6 -> T8 | D3: ='Schema!!!!!!'!D6 -> T11 | E3: ='Schema!!!!!!'!E6 -> T23 | K3: ='Schema!!!!!!'!B17 -> T12 | L3: ='Schema!!!!!!'!C17 -> T4 | M3: ='Schema!!!!!!'!D17 -> T5 | N3: ='Schema!!!!!!'!E17 -> T25 | T3: ='Schema!!!!!!'!F29 -> T14 | U3: ='Schema!!!!!!'!G29 -> T19 | V3: ='Schema!!!!!!'!H29 -> T31 | W3: ='Schema!!!!!!'!I29 -> T26
B5: =B3 -> T2 | E5: =C3 -> T8 | K5: =K3 -> T12 | N5: =L3 -> T4 | T5: =T3 -> T14 | W5: =U3 -> T19 | AC5: Pauze
B8: =D3 -> T11 | E8: =E3 -> T23 | K8: =M3 -> T5 | N8: =N3 -> T25 | T8: =V3 -> T31 | W8: =W3 -> T26
B12: ='Schema!!!!!!'!F1 -> ronde 2 | K12: ='Schema!!!!!!'!F12 -> ronde 5 | T12: ='Schema!!!!!!'!J23 -> ronde 8
B13: =B2 -> Nick’s Weekendspecial | K13: =K2 -> Nick’s Weekendspecial | T13: =T2 -> Nick’s Weekendspecial
B14: ='Schema!!!!!!'!F6 -> T1 | C14: ='Schema!!!!!!'!G6 -> T32 | D14: ='Schema!!!!!!'!H6 -> T24 | E14: ='Schema!!!!!!'!I6 -> T34 | K14: ='Schema!!!!!!'!F17 -> T7 | L14: ='Schema!!!!!!'!G17 -> T9 | M14: ='Schema!!!!!!'!H17 -> T37 | N14: ='Schema!!!!!!'!I17 -> T6 | T14: ='Schema!!!!!!'!J29 -> #REF! | U14: ='Schema!!!!!!'!K29 -> T21 | V14: ='Schema!!!!!!'!L29 -> T38 | W14: ='Schema!!!!!!'!M29 -> T39
B16: =B14 -> T1 | E16: =C14 -> T32 | K16: =K14 -> T7 | N16: =L14 -> T9 | T16: =T14 -> #REF! | W16: =U14 -> T21
B19: =D14 -> T24 | E19: =E14 -> T34 | K19: =M14 -> T37 | N19: =N14 -> T6 | T19: =V14 -> T38 | W19: =W14 -> T39
B26: ='Schema!!!!!!'!J1 -> ronde 3 | K26: ='Schema!!!!!!'!B23 -> ronde 6 | T26: ='Schema!!!!!!'!B34 -> ronde 9
B27: =B2 -> Nick’s Weekendspecial | K27: =K2 -> Nick’s Weekendspecial | T27: =T13 -> Nick’s Weekendspecial
B28: ='Schema!!!!!!'!J6 -> T3 | C28: ='Schema!!!!!!'!K6 -> T15 | D28: ='Schema!!!!!!'!L6 -> T31 | E28: ='Schema!!!!!!'!M6 -> T40 | K28: ='Schema!!!!!!'!B29 -> T10 | L28: ='Schema!!!!!!'!C29 -> T27 | M28: ='Schema!!!!!!'!D29 -> T20 | N28: ='Schema!!!!!!'!E29 -> T38 | T28: ='Schema!!!!!!'!B40 -> T16 | U28: ='Schema!!!!!!'!C40 -> T30 | V28: ='Schema!!!!!!'!D40 -> T28 | W28: ='Schema!!!!!!'!E40 -> T35
B30: =B28 -> T3 | E30: =C28 -> T15 | K30: =K28 -> T10 | N30: =L28 -> T27 | T30: =T28 -> T16 | W30: =U28 -> T30
B33: =D28 -> T31 | E33: =E28 -> T40 | K33: =M28 -> T20 | N33: =N28 -> T38 | T33: =V28 -> T28 | W33: =W28 -> T35

Sheet Danoontje Power
B1: ='Schema!!!!!!'!B1 -> ronde 1 | K1: ='Schema!!!!!!'!B12 -> ronde 4 | T1: ='Schema!!!!!!'!F23 -> ronde 7 | AC1: ='Schema!!!!!!'!F34 -> ronde 10
B2: ='Schema!!!!!!'!A7 -> Danoontje Powerrrrrr | K2: =B2 -> Danoontje Powerrrrrr | T2: =K2 -> Danoontje Powerrrrrr | AC2: =T2 -> Danoontje Powerrrrrr
B3: ='Schema!!!!!!'!B7 -> T7 | C3: ='Schema!!!!!!'!C7 -> T9 | D3: ='Schema!!!!!!'!D7 -> T31 | E3: ='Schema!!!!!!'!E7 -> T34 | K3: ='Schema!!!!!!'!B18 -> T3 | L3: ='Schema!!!!!!'!C18 -> T8 | M3: ='Schema!!!!!!'!D18 -> T11 | N3: ='Schema!!!!!!'!E18 -> T6 | T3: ='Schema!!!!!!'!F30 -> T10 | U3: ='Schema!!!!!!'!G30 -> T21 | V3: ='Schema!!!!!!'!H30 -> T28 | W3: ='Schema!!!!!!'!I30 -> T35
B5: =B3 -> T7 | E5: =C3 -> T9 | K5: =K3 -> T3 | N5: =L3 -> T8 | T5: =T3 -> T10 | W5: =U3 -> T21 | AC5: Pauze
B8: =D3 -> T31 | E8: =E3 -> T34 | K8: =M3 -> T11 | N8: =N3 -> T6 | T8: =V3 -> T28 | W8: =W3 -> T35
B12: ='Schema!!!!!!'!F1 -> ronde 2 | K12: ='Schema!!!!!!'!F12 -> ronde 5 | T12: ='Schema!!!!!!'!J23 -> ronde 8
B13: =B2 -> Danoontje Powerrrrrr | K13: =B13 -> Danoontje Powerrrrrr | T13: =T2 -> Danoontje Powerrrrrr
B14: ='Schema!!!!!!'!F7 -> T2 | C14: ='Schema!!!!!!'!G7 -> T15 | D14: ='Schema!!!!!!'!H7 -> T5 | E14: ='Schema!!!!!!'!I7 -> T40 | K14: ='Schema!!!!!!'!F18 -> T12 | L14: ='Schema!!!!!!'!G18 -> T32 | M14: ='Schema!!!!!!'!H18 -> T24 | N14: ='Schema!!!!!!'!I18 -> T23 | T14: ='Schema!!!!!!'!J30 -> T14 | U14: ='Schema!!!!!!'!K30 -> T30 | V14: ='Schema!!!!!!'!L30 -> T20 | W14: ='Schema!!!!!!'!M30 -> T38
B16: =B14 -> T2 | E16: =C14 -> T15 | K16: =K14 -> T12 | N16: =L14 -> T32 | T16: =T14 -> T14 | W16: =U14 -> T30
B19: =D14 -> T5 | E19: =E14 -> T40 | K19: =M14 -> T24 | N19: =N14 -> T23 | T19: =V14 -> T20 | W19: =W14 -> T38
B26: ='Schema!!!!!!'!J1 -> ronde 3 | K26: ='Schema!!!!!!'!B23 -> ronde 6 | T26: ='Schema!!!!!!'!B34 -> ronde 9
B27: =B2 -> Danoontje Powerrrrrr | K27: =K2 -> Danoontje Powerrrrrr | T27: =T13 -> Danoontje Powerrrrrr
B28: ='Schema!!!!!!'!J7 -> T1 | C28: ='Schema!!!!!!'!K7 -> T4 | D28: ='Schema!!!!!!'!L7 -> T37 | E28: ='Schema!!!!!!'!M7 -> T25 | K28: ='Schema!!!!!!'!B30 -> T16 | L28: ='Schema!!!!!!'!C30 -> T19 | M28: ='Schema!!!!!!'!D30 -> T38 | N28: ='Schema!!!!!!'!E30 -> T39 | T28: ='Schema!!!!!!'!B41 -> #REF! | U28: ='Schema!!!!!!'!C41 -> T27 | V28: ='Schema!!!!!!'!D41 -> T31 | W28: ='Schema!!!!!!'!E41 -> T26
B30: =B28 -> T1 | E30: =C28 -> T4 | K30: =K28 -> T16 | N30: =L28 -> T19 | T30: =T28 -> #REF! | W30: =U28 -> T27
B33: =D28 -> T37 | E33: =E28 -> T25 | K33: =M28 -> T38 | N33: =N28 -> T39 | T33: =V28 -> T31 | W33: =W28 -> T26

Sheet Kamelen race
B1: ='Schema!!!!!!'!B1 -> ronde 1 | K1: ='Schema!!!!!!'!B12 -> ronde 4 | T1: ='Schema!!!!!!'!F23 -> ronde 7 | AC1: ='Schema!!!!!!'!F34 -> ronde 10
B2: ='Schema!!!!!!'!A8 -> Kamelenrace | K2: =B2 -> Kamelenrace | T2: =K2 -> Kamelenrace | AC2: =T2 -> Kamelenrace
B3: ='Schema!!!!!!'!B8 -> T12 | C3: ='Schema!!!!!!'!C8 -> T32 | D3: ='Schema!!!!!!'!D8 -> T37 | E3: ='Schema!!!!!!'!E8 -> T40 | K3: ='Schema!!!!!!'!B19 -> T1 | L3: ='Schema!!!!!!'!C19 -> T9 | M3: ='Schema!!!!!!'!D19 -> T31 | N3: ='Schema!!!!!!'!E19 -> T23 | T3: ='Schema!!!!!!'!F31 -> T16 | U3: ='Schema!!!!!!'!G31 -> T30 | V3: ='Schema!!!!!!'!H31 -> T20 | W3: ='Schema!!!!!!'!I31 -> T39
B5: =B3 -> T12 | E5: =C3 -> T32 | K5: =K3 -> T1 | N5: =L3 -> T9 | T5: =T3 -> T16 | W5: =U3 -> T30 | AC5: Pauze
B8: =D3 -> T37 | E8: =E3 -> T40 | K8: =M3 -> T31 | N8: =N3 -> T23 | T8: =V3 -> T20 | W8: =W3 -> T39
B12: ='Schema!!!!!!'!F1 -> ronde 2 | K12: ='Schema!!!!!!'!F12 -> ronde 5 | T12: ='Schema!!!!!!'!J23 -> ronde 8
B13: =B2 -> Kamelenrace | K13: =K2 -> Kamelenrace | T13: =T2 -> Kamelenrace
B14: ='Schema!!!!!!'!F8 -> T7 | C14: ='Schema!!!!!!'!G8 -> T4 | D14: ='Schema!!!!!!'!H8 -> T11 | E14: ='Schema!!!!!!'!I8 -> T25 | K14: ='Schema!!!!!!'!F19 -> T3 | L14: ='Schema!!!!!!'!G19 -> T15 | M14: ='Schema!!!!!!'!H19 -> T5 | N14: ='Schema!!!!!!'!I19 -> T34 | O14: ='Schema!!!!!!'!J19 -> 0 | T14: ='Schema!!!!!!'!J31 -> T10 | U14: ='Schema!!!!!!'!K31 -> T27 | V14: ='Schema!!!!!!'!L31 -> T31 | W14: ='Schema!!!!!!'!M31 -> T35
B16: =B14 -> T7 | E16: =C14 -> T4 | K16: =K14 -> T3 | N16: =L14 -> T15 | T16: =T14 -> T10 | W16: =U14 -> T27
B19: =D14 -> T11 | E19: =E14 -> T25 | K19: =M14 -> T5 | N19: =N14 -> T34 | T19: =V14 -> T31 | W19: =W14 -> T35
B26: ='Schema!!!!!!'!J1 -> ronde 3 | K26: ='Schema!!!!!!'!B23 -> ronde 6 | T26: ='Schema!!!!!!'!B34 -> ronde 9
B27: =B2 -> Kamelenrace | K27: =K2 -> Kamelenrace | T27: =T13 -> Kamelenrace
B28: ='Schema!!!!!!'!J8 -> T2 | C28: ='Schema!!!!!!'!K8 -> T8 | D28: ='Schema!!!!!!'!L8 -> T24 | E28: ='Schema!!!!!!'!M8 -> T6 | K28: ='Schema!!!!!!'!B31 -> #REF! | L28: ='Schema!!!!!!'!C31 -> T21 | M28: ='Schema!!!!!!'!D31 -> T28 | N28: ='Schema!!!!!!'!E31 -> T26 | T28: ='Schema!!!!!!'!B42 -> T14 | U28: ='Schema!!!!!!'!C42 -> T19 | V28: ='Schema!!!!!!'!D42 -> T38 | W28: ='Schema!!!!!!'!E42 -> T38
B30: =B28 -> T2 | E30: =C28 -> T8 | K30: =K28 -> #REF! | N30: =L28 -> T21 | T30: =T28 -> T14 | W30: =U28 -> T19
B33: =D28 -> T24 | E33: =E28 -> T6 | K33: =M28 -> T28 | N33: =N28 -> T26 | T33: =V28 -> T38 | W33: =W28 -> T38

Sheet Memory Romy
B1: ='Schema!!!!!!'!B1 -> ronde 1 | K1: ='Schema!!!!!!'!B12 -> ronde 4 | T1: ='Schema!!!!!!'!F23 -> ronde 7 | AC1: ='Schema!!!!!!'!F34 -> ronde 10
B2: ='Schema!!!!!!'!A43 -> Memory Romy | K2: =B2 -> Memory Romy | T2: =K2 -> Memory Romy | AC2: =T2 -> Memory Romy
B3: ='Schema!!!!!!'!B9 -> T3 | C3: ='Schema!!!!!!'!C9 -> T15 | D3: ='Schema!!!!!!'!D9 -> T24 | E3: ='Schema!!!!!!'!E9 -> T25 | K3: ='Schema!!!!!!'!B20 -> T2 | L3: ='Schema!!!!!!'!C20 -> T32 | M3: ='Schema!!!!!!'!D20 -> T37 | N3: ='Schema!!!!!!'!E20 -> T34 | T3: ='Schema!!!!!!'!F32 -> #REF! | U3: ='Schema!!!!!!'!G32 -> T27 | V3: ='Schema!!!!!!'!H32 -> T38 | W3: ='Schema!!!!!!'!I32 -> T38
B5: =B3 -> T3 | E5: =C3 -> T15 | K5: =K3 -> T2 | N5: =L3 -> T32 | T5: =T3 -> #REF! | W5: =U3 -> T27 | AC5: Pauze
B8: =D3 -> T24 | E8: =E3 -> T25 | K8: =M3 -> T37 | N8: =N3 -> T34 | T8: =V3 -> T38 | W8: =W3 -> T38
B12: ='Schema!!!!!!'!F1 -> ronde 2 | K12: ='Schema!!!!!!'!F12 -> ronde 5 | T12: ='Schema!!!!!!'!J23 -> ronde 8
B13: =B2 -> Memory Romy | K13: =K2 -> Memory Romy | T13: =T2 -> Memory Romy
B14: ='Schema!!!!!!'!F9 -> T12 | C14: ='Schema!!!!!!'!G9 -> T8 | D14: ='Schema!!!!!!'!H9 -> T31 | E14: ='Schema!!!!!!'!I9 -> T6 | K14: ='Schema!!!!!!'!F20 -> T1 | L14: ='Schema!!!!!!'!G20 -> T4 | M14: ='Schema!!!!!!'!H20 -> T11 | N14: ='Schema!!!!!!'!I20 -> T40 | T14: ='Schema!!!!!!'!J32 -> T16 | U14: ='Schema!!!!!!'!K32 -> T19 | V14: ='Schema!!!!!!'!L32 -> T28 | W14: ='Schema!!!!!!'!M32 -> T26
B16: =B14 -> T12 | E16: =C14 -> T8 | K16: =K14 -> T1 | N16: =L14 -> T4 | T16: =T14 -> T16 | W16: =U14 -> T19
B19: =D14 -> T31 | E19: =E14 -> T6 | K19: =M14 -> T11 | N19: =N14 -> T40 | T19: =V14 -> T28 | W19: =W14 -> T26
B26: ='Schema!!!!!!'!J1 -> ronde 3 | K26: ='Schema!!!!!!'!B23 -> ronde 6 | T26: ='Schema!!!!!!'!B34 -> ronde 9
B27: =B2 -> Memory Romy | K27: =K2 -> Memory Romy | T27: =T13 -> Memory Romy
B28: ='Schema!!!!!!'!J9 -> T7 | C28: ='Schema!!!!!!'!K9 -> T9 | D28: ='Schema!!!!!!'!L9 -> T5 | E28: ='Schema!!!!!!'!M9 -> T23 | K28: ='Schema!!!!!!'!B32 -> T14 | L28: ='Schema!!!!!!'!C32 -> T30 | M28: ='Schema!!!!!!'!D32 -> T31 | N28: ='Schema!!!!!!'!E32 -> T35 | T28: ='Schema!!!!!!'!B43 -> T10 | U28: ='Schema!!!!!!'!C43 -> T21 | V28: ='Schema!!!!!!'!D43 -> T20 | W28: ='Schema!!!!!!'!E43 -> T39
B30: =B28 -> T7 | E30: =C28 -> T9 | K30: =K28 -> T14 | N30: =L28 -> T30 | T30: =T28 -> T10 | W30: =U28 -> T21
B33: =D28 -> T5 | E33: =E28 -> T23 | K33: =M28 -> T31 | N33: =N28 -> T35 | T33: =V28 -> T20 | W33: =W28 -> T39
